<?xml version="1.0" encoding="utf-8"?>
<!-- This URDF was automatically created by SolidWorks to URDF Exporter! Originally created by Stephen Brawner (brawner@gmail.com) 
     Commit Version: 1.6.0-4-g7f85cfe  Build Version: 1.6.7995.38578
     For more information, please see http://wiki.ros.org/sw_urdf_exporter -->
<robot
  name="scara_urdf">
  <link
    name="base_link">
    <inertial>
      <origin
        xyz="-0.072445 -0.0016949 0.13495"
        rpy="0 0 0" />
      <mass
        value="2.4384" />
      <inertia
        ixx="0.0057214"
        ixy="5.7529E-06"
        ixz="-0.00021594"
        iyy="0.01402"
        iyz="-4.8187E-05"
        izz="0.013505" />
    </inertial>
    <visual>
      <origin
        xyz="0 0 0"
        rpy="0 0 0" />
      <geometry>
        <mesh
          filename="package://scara_urdf/meshes/base_link.STL" />
      </geometry>
      <material
        name="">
        <color
          rgba="0.5 0.5 0.9 1" />
      </material>
    </visual>
    <collision>
      <origin
        xyz="0 0 0"
        rpy="0 0 0" />
      <geometry>
        <mesh
          filename="package://scara_urdf/meshes/base_link.STL" />
      </geometry>
    </collision>
  </link>
  <link
    name="link1">
    <inertial>
      <origin
        xyz="0.053526 7.6065E-06 0.039571"
        rpy="0 0 0" />
      <mass
        value="0.67597" />
      <inertia
        ixx="0.00039875"
        ixy="1.004E-07"
        ixz="7.7183E-07"
        iyy="0.0015746"
        iyz="-4.5317E-07"
        izz="0.0016679" />
    </inertial>
    <visual>
      <origin
        xyz="0 0 0"
        rpy="0 0 0" />
      <geometry>
        <mesh
          filename="package://scara_urdf/meshes/link1.STL" />
      </geometry>
      <material
        name="">
        <color
          rgba="0.5 0.9 0.5 1" />
      </material>
    </visual>
    <collision>
      <origin
        xyz="0 0 0"
        rpy="0 0 0" />
      <geometry>
        <mesh
          filename="package://scara_urdf/meshes/link1.STL" />
      </geometry>
    </collision>
  </link>
  <joint
    name="joint1"
    type="revolute">
    <origin
      xyz="0 0 0.1685"
      rpy="0 0 0" />
    <parent
      link="base_link" />
    <child
      link="link1" />
    <axis
      xyz="0 0 -1" />
    <limit
      lower="2"
      upper="2"
      effort="0"
      velocity="0" />
  </joint>
  <link
    name="link2">
    <inertial>
      <origin
        xyz="0.071771 -5.4271E-06 0.051655"
        rpy="0 0 0" />
      <mass
        value="0.45238" />
      <inertia
        ixx="0.00041579"
        ixy="2.6015E-09"
        ixz="-3.3379E-06"
        iyy="0.0011455"
        iyz="1.6668E-08"
        izz="0.0012642" />
    </inertial>
    <visual>
      <origin
        xyz="0 0 0"
        rpy="0 0 0" />
      <geometry>
        <mesh
          filename="package://scara_urdf/meshes/link2.STL" />
      </geometry>
      <material
        name="">
        <color
          rgba="0.9 0.5 0.5 1" />
      </material>
    </visual>
    <collision>
      <origin
        xyz="0 0 0"
        rpy="0 0 0" />
      <geometry>
        <mesh
          filename="package://scara_urdf/meshes/link2.STL" />
      </geometry>
    </collision>
  </link>
  <joint
    name="joint2"
    type="revolute">
    <origin
      xyz="0.18 0 0.012"
      rpy="0 0 0" />
    <parent
      link="link1" />
    <child
      link="link2" />
    <axis
      xyz="0 0 -1" />
    <limit
      lower="2.8"
      upper="2"
      effort="0"
      velocity="0" />
  </joint>
  <link
    name="endZ">
    <inertial>
      <origin
        xyz="0.00023774 -7.5992E-05 0.0071622"
        rpy="0 0 0" />
      <mass
        value="0.0047788" />
      <inertia
        ixx="2.1565E-07"
        ixy="-2.2784E-09"
        ixz="-1.5351E-09"
        iyy="2.1033E-07"
        iyz="3.4652E-10"
        izz="3.4179E-07" />
    </inertial>
    <visual>
      <origin
        xyz="0 0 0"
        rpy="0 0 0" />
      <geometry>
        <mesh
          filename="package://scara_urdf/meshes/endZ.STL" />
      </geometry>
      <material
        name="">
        <color
          rgba="0.3 0.3 0.3 1" />
      </material>
    </visual>
    <collision>
      <origin
        xyz="0 0 0"
        rpy="0 0 0" />
      <geometry>
        <mesh
          filename="package://scara_urdf/meshes/endZ.STL" />
      </geometry>
    </collision>
  </link>
  <joint
    name="jointz"
    type="prismatic">
    <origin
      xyz="0.18 0 0.12133"
      rpy="0 0 0" />
    <parent
      link="link2" />
    <child
      link="endZ" />
    <axis
      xyz="0 0 -1" />
    <limit
      lower="0"
      upper="0.08"
      effort="0"
      velocity="0" />
  </joint>
  <link
    name="endR">
    <inertial>
      <origin
        xyz="6.2902E-08 4.1238E-07 0.11272"
        rpy="0 0 0" />
      <mass
        value="0.012412" />
      <inertia
        ixx="4.4942E-05"
        ixy="-2.1031E-09"
        ixz="8.0658E-11"
        iyy="4.4941E-05"
        iyz="1.7788E-10"
        izz="1.6452E-07" />
    </inertial>
    <visual>
      <origin
        xyz="0 0 0"
        rpy="0 0 0" />
      <geometry>
        <mesh
          filename="package://scara_urdf/meshes/endR.STL" />
      </geometry>
      <material
        name="">
        <color
          rgba="0.8 0.8 0.8 1" />
      </material>
    </visual>
    <collision>
      <origin
        xyz="0 0 0"
        rpy="0 0 0" />
      <geometry>
        <mesh
          filename="package://scara_urdf/meshes/endR.STL" />
      </geometry>
    </collision>
  </link>
  <joint
    name="jointr"
    type="continuous">
    <origin
      xyz="0 0 -0.1969"
      rpy="0 0 0" />
    <parent
      link="endZ" />
    <child
      link="endR" />
    <axis
      xyz="0 0 -1" />
  </joint>
</robot>